<?xml version="1.0"?>
<robot name="my_model" >

  <material name="white">
    <color rgba="1 1 1 1"/>
  </material>

  <!-- Base -->
  <link name="base_link">
    <visual>
      <geometry>
        <mesh filename="package://my_home_urdf/meshes/chassis.dae"/>
      </geometry>
    </visual>
    <collision>
      <geometry>
        <mesh filename="package://my_home_urdf/meshes/chassis.dae"/>
      </geometry>
    </collision>
    <inertial>
      <mass value="15"/>
      <inertia ixx="1.0" ixy="0.0" ixz="0.0" iyy="1.0" iyz="0.0" izz="1.0"/>
    </inertial>
  </link>

  <!-- Right Wheel -->
 <link name="right_wheel_link">
    <visual>
      <geometry>
        <cylinder length="0.05" radius="0.12"/>
      </geometry>
      <origin rpy="1.57075 0 0"/>
      <material name="white"/>
    </visual>
    <collision>
      <geometry>
        <cylinder length="0.05" radius="0.12"/>
      </geometry>
      <origin rpy="1.57075 0 0"/>
    </collision>
    <inertial>
      <mass value="6"/>
      <inertia ixx="1.0" ixy="0.0" ixz="0.0" iyy="1.0" iyz="0.0" izz="1.0"/>
    </inertial>
  </link>

 <!-- Base and Right Wheel Joint -->
 <joint name="base_to_right_wheel_joint" type="continuous">
    <axis xyz="0 1 0"/>
    <parent link="base_link"/>
    <child link="right_wheel_link"/>
    <origin xyz="-0.1 -0.16 -0.1"/>
 </joint>

<!-- Left Wheel -->
 <link name="left_wheel_link">
    <visual>
      <geometry>
        <cylinder length="0.05" radius="0.12"/>
      </geometry>
      <origin rpy="1.57075 0 0"/>
      <material name="white"/>
    </visual>
    <collision>
      <geometry>
        <cylinder length="0.05" radius="0.12"/>
      </geometry>
      <origin rpy="1.57075 0 0"/>
    </collision>
    <inertial>
      <mass value="6"/>
      <inertia ixx="1.0" ixy="0.0" ixz="0.0" iyy="1.0" iyz="0.0" izz="1.0"/>
    </inertial>
 </link>

  <!-- Base and Left Wheel Joint -->
  <joint name="base_to_left_wheel_joint" type="continuous">
   <axis xyz="0 1 0"/>
    <parent link="base_link"/>
    <child link="left_wheel_link"/>
    <origin xyz="-0.1 0.16 -0.1"/>
 </joint>

 <!-- Caster -->
  <link name="common_caster_link">
  </link>

 <link name="caster_link">
    <visual>
      <geometry>
        <sphere radius="0.062"/>
      </geometry>
      <material name="white"/>
    </visual>
    <collision>
      <geometry>
        <sphere radius="0.062"/>
      </geometry>
      <origin xyz="0.17 0 -0.15"/>
    </collision>
    <inertial>
      <mass value="5"/>
      <inertia ixx="1.0" ixy="0.0" ixz="0.0" iyy="1.0" iyz="0.0" izz="1.0"/>
    </inertial>
 </link>

<!-- Base and Caster Joint 1 -->
 <joint name="base_to_common_caster_joint_y" type="continuous">
    <axis xyz="0 1 0"/>
    <parent link="base_link"/>
    <child link="common_caster_link"/>
    <origin xyz="0.17 0 -0.15"/>
 </joint>

 <!-- Base and Caster Joint 2 -->
 <joint name="common_caster_to_caster_joint_x" type="continuous">
    <axis xyz="1 0 0"/>
    <parent link="common_caster_link"/>
    <child link="caster_link"/>
 </joint>

 <!--Manipulator Base-->
 <link name="manipulator_base_link">
    <visual>
      <geometry>
        <cylinder length="0.15" radius="0.06"/>
      </geometry>
      <material name="white"/>
    </visual>
    <collision>
      <geometry>
        <cylinder length="0.15" radius="0.06"/>
      </geometry>
      <origin xyz="0.14 0 0.1"/>
    </collision>
    <inertial>
      <mass value="7"/>
      <inertia ixx="1.0" ixy="0.0" ixz="0.0" iyy="1.0" iyz="0.0" izz="1.0"/>
    </inertial>
 </link>

  <!-- Base and Manipulator Base Joint-->
 <joint name="base_to_manipulator_base_joint" type="revolute">
    <axis xyz="0 0 1"/>
    <limit effort="1000.0" lower="-1.7" upper="1.7" velocity="0.5"/>
    <parent link="base_link"/>
    <child link="manipulator_base_link"/>
    <origin xyz="0.14 0 0.1"/>
 </joint> 

  <!--Manipulator Shoulder Link-->
 <link name="manipulator_shoulder_link">
    <visual>
      <geometry>
        <box size="0.3 0.025 0.025"/>
      </geometry>
      <material name="white"/>
    </visual>
    <collision>
      <geometry>
        <box size="0.3 0.025 0.025"/>
      </geometry>
      <origin xyz="0.1 0 -0.01" />
    </collision>
    <inertial>
      <mass value="4"/>
      <inertia ixx="1.0" ixy="0.0" ixz="0.0" iyy="1.0" iyz="0.0" izz="1.0"/>
    </inertial>
 </link>

  <!-- Manipulator Base and Manipulator Shoulder Joint-->
 <joint name="manipulator_base_to_shoulder_joint" type="revolute">
    <axis xyz="0 1 0"/>
    <limit effort="1000.0" lower="-0.45" upper="0.11" velocity="0.5"/>
    <parent link="manipulator_base_link"/>
    <child link="manipulator_shoulder_link"/>
    <origin xyz="0.1 0 -0.01" />
 </joint> 

 <!--Left Gripper 1-->
 <link name="left_gripper_1">
    <visual>
      <geometry>
        <box size="0.02 0.02 0.02"/>
      </geometry>
      <material name="white"/>
    </visual>
    <collision>
      <geometry>
        <box size="0.02 0.02 0.02"/>
      </geometry>
      <origin xyz="0.15 0.02 0" />
    </collision>
    <inertial>
      <mass value="2"/>
      <inertia ixx="1.0" ixy="0.0" ixz="0.0" iyy="1.0" iyz="0.0" izz="1.0"/>
    </inertial>
 </link>

  <!-- Manipulator Shoulder and Left Gripper 1 Joint-->
 <joint name="manipulator_shoulder_to_left_gripper_1_joint" type="revolute">
    <axis xyz="0 0 1"/>
    <limit effort="1000.0" lower="-0.45" upper="0.4" velocity="0.5"/>
    <parent link="manipulator_shoulder_link"/>
    <child link="left_gripper_1"/>
    <origin xyz="0.15 0.02 0" />
 </joint> 

 <!--Right Gripper 1-->
 <link name="right_gripper_1">
    <visual>
      <geometry>
        <box size="0.02 0.02 0.02"/>
      </geometry>
      <material name="white"/>
    </visual>
    <collision>
      <geometry>
        <box size="0.02 0.02 0.02"/>
      </geometry>
      <origin xyz="0.15 -0.02 0" />
    </collision>
    <inertial>
      <mass value="2"/>
      <inertia ixx="1.0" ixy="0.0" ixz="0.0" iyy="1.0" iyz="0.0" izz="1.0"/>
    </inertial>
 </link>

  <!-- Manipulator Shoulder and Right Gripper 1 Joint-->
 <joint name="manipulator_shoulder_to_right_gripper_1_joint" type="revolute">
    <axis xyz="0 0 1"/>
    <limit effort="1000.0" lower="-0.4" upper="0.45" velocity="0.5"/>
    <parent link="manipulator_shoulder_link"/>
    <child link="right_gripper_1"/>
    <origin xyz="0.15 -0.02 0" />
 </joint> 

 <!--Left Gripper 2-->
 <link name="left_gripper_2">
    <visual>
      <geometry>
        <box size="0.015 0.05 0.015"/>
      </geometry>
      <material name="white"/>
    </visual>
    <collision>
      <geometry>
        <box size="0.015 0.05 0.015"/>
      </geometry>
      <origin rpy="0 0 0.79" xyz="0.018 0.003 0" />
    </collision>
    <inertial>
      <mass value="2"/>
      <inertia ixx="1.0" ixy="0.0" ixz="0.0" iyy="1.0" iyz="0.0" izz="1.0"/>
    </inertial>
 </link>

 <!-- Left Gripper 1 and Left Gripper 2 Joint-->
 <joint name="left_gripper_1_to_left_gripper_2_joint" type="revolute">
    <axis xyz="0 0 1"/>
    <limit effort="1000.0" lower="0.1" upper="0.6" velocity="0.5"/>
    <parent link="left_gripper_1"/>
    <child link="left_gripper_2"/>
    <origin rpy="0 0 0.79" xyz="0.018 0.003 0" />
 </joint>

 <!--Right Gripper 2-->
 <link name="right_gripper_2">
    <visual>
      <geometry>
        <box size="0.015 0.05 0.015"/>
      </geometry>
      <material name="white"/>
    </visual>
    <collision>
      <geometry>
        <box size="0.015 0.05 0.015"/>
      </geometry>
      <origin rpy="0 0 -0.79" xyz="0.018 -0.003 0" />
    </collision>
    <inertial>
      <mass value="2"/>
      <inertia ixx="1.0" ixy="0.0" ixz="0.0" iyy="1.0" iyz="0.0" izz="1.0"/>
    </inertial>
 </link>

 <!-- Right Gripper 1 and Right Gripper 2 Joint-->
 <joint name="right_gripper_1_to_right_gripper_2_joint" type="revolute">
    <axis xyz="0 0 1"/>
    <limit effort="1000.0" lower="-0.1" upper="-0.6" velocity="0.5"/>
    <parent link="right_gripper_1"/>
    <child link="right_gripper_2"/>
    <origin rpy="0 0 -0.79" xyz="0.018 -0.003 0" />
 </joint>

</robot>