<?xml version="1.0"?>
<robot name="my_model" xmlns:xacro="http://ros.org/wiki/xacro">
    <xacro:property name="pi" value="3.1415" />

    <material name="white">
        <color rgba="1 1 1 1"/>
    </material>

    <xacro:macro name="default_inertial" params="mass">
        <inertial>
            <mass value="${mass}" />
        <inertia ixx="1.0" ixy="0.0" ixz="0.0" iyy="1.0" iyz="0.0" izz="1.0" />
        </inertial>
    </xacro:macro>

    <link name="base_link">
        <visual>
            <geometry>
                <mesh filename="package://my_home_urdf/meshes/chassis.dae"/>
            </geometry>
        </visual>
        <collision>
            <geometry>
                <mesh filename="package://my_home_urdf/meshes/chassis.dae"/>
            </geometry>
        </collision>
        <xacro:default_inertial mass="15"/>
    </link>

    <xacro:macro name="wheel" params="prefix reflect">

        <link name="${prefix}_wheel">
            <visual>
                <origin rpy="${pi/2} 0 0" />
                <geometry>
                    <cylinder length="0.05" radius="0.12"/>
                </geometry>
                <material name="white"/>
            </visual>
            <collision>
                <origin rpy="${pi/2} 0 0" />
                <geometry>
                    <cylinder length="0.05" radius="0.12"/>
                </geometry>
            </collision>
            <xacro:default_inertial mass="5"/>
        </link>

        <joint name="base_to_${prefix}_wheel_joint" type="continuous">
            <axis xyz="0 1 0"/>
            <parent link="base_link"/>
            <child link="${prefix}_wheel"/>
            <origin xyz="-0.1 ${reflect * 0.16} -0.1"/>
        </joint>

    </xacro:macro>

    <xacro:wheel prefix="right" reflect="-1"/>
    <xacro:wheel prefix="left" reflect="1"/>

    <link name="caster">
        <visual>
            <geometry>
                <sphere radius="0.062"/>
            </geometry>
            <material name="white"/>
        </visual>
        <collision>
            <geometry>
                <sphere radius="0.062"/>
            </geometry>
        </collision>
        <inertial>
            <mass value="4"/>
            <inertia ixx="1.0" ixy="0.0" ixz="0.0" iyy="1.0" iyz="0.0" izz="1.0"/>
        </inertial>
    </link>

    <joint name="base_to_caster_joint" type="continuous">
        <axis xyz="0 1 0"/>
        <parent link="base_link"/>
        <child link="caster"/>
        <origin xyz="0.17 0 -0.15"/>
    </joint>

    <link name="common_caster">
    </link>

    <joint name="caster_to_common_caster_joint" type="continuous">
        <axis xyz="1 0 0"/>
        <parent link="caster"/>
        <child link="common_caster"/>
    </joint>
    
</robot>